<?xml version="1.0" ?>
<!-- =================================================================================== -->
<!-- |    This document was autogenerated by xacro from dhpr.urdf.xacro                | -->
<!-- |    EDITING THIS FILE BY HAND IS NOT RECOMMENDED                                 | -->
<!-- =================================================================================== -->
<robot name="dhpr">
  <!-- Plugins -->
  <gazebo>
    <!-- Diff_Drive_Plugin -->
    <plugin filename="gz-sim-diff-drive-system" name="gz::sim::systems::DiffDrive">
      <!-- Topic for the command input -->
      <topic>/cmd_vel</topic>
      <!-- Wheel joints -->
      <left_joint>front_left_wheel_joint</left_joint>
      <left_joint>rear_left_wheel_joint</left_joint>
      <right_joint>front_right_wheel_joint</right_joint>
      <right_joint>rear_right_wheel_joint</right_joint>
      <!-- Wheel parameters -->
      <wheel_separation>0.7</wheel_separation>
      <wheel_radius>0.10</wheel_radius>
      <!-- Control gains and limits (optional) -->
      <max_velocity>3.0</max_velocity>
      <max_linear_acceleration>1</max_linear_acceleration>
      <min_linear_acceleration>-1</min_linear_acceleration>
      <max_angular_acceleration>2</max_angular_acceleration>
      <min_angular_acceleration>-2</min_angular_acceleration>
      <max_linear_velocity>0.5</max_linear_velocity>
      <min_linear_velocity>-0.5</min_linear_velocity>
      <max_angular_velocity>1</max_angular_velocity>
      <min_angular_velocity>-1</min_angular_velocity>
      <!-- Other parameters (optional) -->
      <odom_topic>odom</odom_topic>
      <tf_topic>tf</tf_topic>
      <frame_id>odom</frame_id>
      <child_frame_id>base_footprint</child_frame_id>
      <odom_publish_frequency>30</odom_publish_frequency>
    </plugin>
    <!-- Joint_State_Plugin -->
    <plugin filename="gz-sim-joint-state-publisher-system" name="gz::sim::systems::JointStatePublisher">
      <topic>joint_states</topic>
      <joint_name>front_left_wheel_joint</joint_name>
      <joint_name>front_right_wheel_joint</joint_name>
      <joint_name>rear_left_wheel_joint</joint_name>
      <joint_name>rear_right_wheel_joint</joint_name>
    </plugin>
  </gazebo>
  <!-- Lidar -->
  <gazebo reference="lidar_link">
    <sensor name="gpu_lidar" type="gpu_lidar">
      <pose>0 0 0 0 0 0</pose>
      <always_on>true</always_on>
      <visualize>true</visualize>
      <update_rate>10</update_rate>
      <topic>scan</topic>
      <!-- Important tag for gz_brdige communication -->
      <gz_frame_id>lidar_link</gz_frame_id>
      <lidar>
        <scan>
          <!-- 2D Lidar -->
          <horizontal>
            <samples>360</samples>
            <min_angle>-3.14</min_angle>
            <max_angle>3.14</max_angle>
          </horizontal>
          <!-- Include for 3D Lidar -->
          <vertical>
            <samples>40</samples>
            <min_angle>-0.186</min_angle>
            <max_angle>0.186</max_angle>
          </vertical>
        </scan>
        <range>
          <min>0.3</min>
          <max>12</max>
        </range>
      </lidar>
    </sensor>
  </gazebo>
  <!-- Materials -->
  <material name="black">
    <color rgba="0.0 0.0 0.0 1.0"/>
  </material>
  <material name="white">
    <color rgba="1.0 1.0 1.0 1.0"/>
  </material>
  <material name="red">
    <color rgba="0.8 0.0 0.0 1.0"/>
  </material>
  <material name="blue">
    <color rgba="0.0 0.0 0.8 1.0"/>
  </material>
  <material name="green">
    <color rgba="0.0 0.8 0.0 1.0"/>
  </material>
  <material name="grey">
    <color rgba="0.5 0.5 0.5 1.0"/>
  </material>
  <material name="orange">
    <color rgba="1.0 0.4235294117647059 0.0392156862745098 1.0"/>
  </material>
  <material name="brown">
    <color rgba="0.8705882352941177 0.8117647058823529 0.7647058823529411 1.0"/>
  </material>
  <!-- BaseFootprint -->
  <link name="base_footprint"/>
  <!-- Joint BaseFootprint -> BaseLink -->
  <joint name="base_footprint_joint" type="fixed">
    <origin rpy="0 0 0" xyz="0 0 0.1"/>
    <parent link="base_footprint"/>
    <child link="base_link"/>
  </joint>
  <!-- BaseLink -->
  <link name="base_link">
    <pose>0 0 0.1 0 0 0</pose>
    <inertial>
      <mass value="15.0"/>
      <origin rpy=" 0 0 0" xyz="0 0 0.1"/>
      <inertia ixx="0.6624999999999999" ixy="0" ixz="0" iyy="0.8500000000000002" iyz="0" izz="1.4125000000000003"/>
    </inertial>
    <collision name="collision">
      <origin rpy=" 0 0 0" xyz="0 0 0.1"/>
      <geometry>
        <box size="0.8 0.7 0.2"/>
      </geometry>
    </collision>
    <visual name="base_link_visual">
      <material name="grey"/>
      <origin rpy=" 0 0 0" xyz="0 0 0.1"/>
      <geometry>
        <box size="0.8 0.7 0.2"/>
      </geometry>
    </visual>
  </link>
  <!-- Joint BaseLink -> FrontLeftWheel -->
  <joint name="front_left_wheel_joint" type="continuous">
    <origin rpy="0 0 0" xyz="0.25 0.38 0.05"/>
    <child link="front_left_wheel"/>
    <parent link="base_link"/>
    <axis rpy="0 0 0" xyz="0 1 0"/>
    <limit effort="100" velocity="10"/>
    <dynamics damping="1.0" friction="1.0"/>
  </joint>
  <!-- FrontLeftWheel -->
  <link name="front_left_wheel">
    <inertial>
      <mass value="5.0"/>
      <origin rpy="0 1.5707 1.5707" xyz="0 0 0"/>
      <inertia ixx="0.014" ixy="0" ixz="0" iyy="0.014" iyz="0" izz="0.025"/>
    </inertial>
    <collision>
      <origin rpy="0 1.5707 1.5707" xyz="0 0 0"/>
      <geometry>
        <cylinder length="0.10" radius="0.15"/>
      </geometry>
    </collision>
    <visual name="front_left_wheel_visual">
      <material name="orange"/>
      <origin rpy="0 1.5707 1.5707" xyz="0 0 0"/>
      <geometry>
        <cylinder length="0.10" radius="0.15"/>
      </geometry>
    </visual>
  </link>
  <!-- Joint BaseLink -> FrontRightWheel -->
  <joint name="front_right_wheel_joint" type="continuous">
    <origin rpy="0 0 0" xyz="0.25 -0.38 0.05"/>
    <child link="front_right_wheel"/>
    <parent link="base_link"/>
    <axis rpy="0 0 0" xyz="0 1 0"/>
    <limit effort="100" velocity="10"/>
    <dynamics damping="1.0" friction="1.0"/>
  </joint>
  <!-- FrontRightWheel -->
  <link name="front_right_wheel">
    <inertial>
      <mass value="5.0"/>
      <origin rpy="0 1.5707 1.5707" xyz="0 0 0"/>
      <inertia ixx="0.014" ixy="0" ixz="0" iyy="0.014" iyz="0" izz="0.025"/>
    </inertial>
    <collision>
      <origin rpy="0 1.5707 1.5707" xyz="0 0 0"/>
      <geometry>
        <cylinder length="0.10" radius="0.15"/>
      </geometry>
    </collision>
    <visual name="front_right_wheel_visual">
      <material name="orange"/>
      <origin rpy="0 1.5707 1.5707" xyz="0 0 0"/>
      <geometry>
        <cylinder length="0.10" radius="0.15"/>
      </geometry>
    </visual>
  </link>
  <!-- Joint BaseLink -> RearLeftWheel -->
  <joint name="rear_left_wheel_joint" type="continuous">
    <origin rpy="0 0 0" xyz="-0.25 0.38 0.05"/>
    <child link="rear_left_wheel"/>
    <parent link="base_link"/>
    <axis rpy="0 0 0" xyz="0 1 0"/>
    <limit effort="100" velocity="10"/>
    <dynamics damping="1.0" friction="1.0"/>
  </joint>
  <!-- LeftWheel -->
  <link name="rear_left_wheel">
    <inertial>
      <mass value="5.0"/>
      <origin rpy="0 1.5707 1.5707" xyz="0 0 0"/>
      <inertia ixx="0.014" ixy="0" ixz="0" iyy="0.014" iyz="0" izz="0.025"/>
    </inertial>
    <collision>
      <origin rpy="0 1.5707 1.5707" xyz="0 0 0"/>
      <geometry>
        <cylinder length="0.10" radius="0.15"/>
      </geometry>
    </collision>
    <visual name="rear_left_wheel_visual">
      <material name="orange"/>
      <origin rpy="0 1.5707 1.5707" xyz="0 0 0"/>
      <geometry>
        <cylinder length="0.10" radius="0.15"/>
      </geometry>
    </visual>
  </link>
  <!-- Joint BaseLink -> RearRightWheel -->
  <joint name="rear_right_wheel_joint" type="continuous">
    <origin rpy="0 0 0" xyz="-0.25 -0.38 0.05"/>
    <child link="rear_right_wheel"/>
    <parent link="base_link"/>
    <axis rpy="0 0 0" xyz="0 1 0"/>
    <limit effort="100" velocity="10"/>
    <dynamics damping="1.0" friction="1.0"/>
  </joint>
  <!-- RightWheel -->
  <link name="rear_right_wheel">
    <inertial>
      <mass value="5.0"/>
      <origin rpy="0 1.5707 1.5707" xyz="0 0 0"/>
      <inertia ixx="0.014" ixy="0" ixz="0" iyy="0.014" iyz="0" izz="0.025"/>
    </inertial>
    <collision>
      <origin rpy="0 1.5707 1.5707" xyz="0 0 0"/>
      <geometry>
        <cylinder length="0.10" radius="0.15"/>
      </geometry>
    </collision>
    <visual name="rear_right_wheel_visual">
      <material name="orange"/>
      <origin rpy="0 1.5707 1.5707" xyz="0 0 0"/>
      <geometry>
        <cylinder length="0.10" radius="0.15"/>
      </geometry>
    </visual>
  </link>
  <!-- Joint BaseLink -> Lidar -->
  <joint name="lidar_joint" type="fixed">
    <origin rpy="0 0 0" xyz="0 0 0.20"/>
    <child link="lidar_link"/>
    <parent link="base_link"/>
  </joint>
  <!-- Lidar -->
  <link name="lidar_link">
    <inertial>
      <mass value="0.3"/>
      <origin rpy="0 0 0" xyz="0 0 0"/>
      <inertia ixx="0.0013125" ixy="0" ixz="0" iyy="0.0013125" iyz="0" izz="0.0015"/>
    </inertial>
    <collision>
      <origin rpy="0 0 0" xyz="0 0 0"/>
      <geometry>
        <box size="0.15 0.15 0.15"/>
      </geometry>
    </collision>
    <visual name="lidar_link_visual">
      <material name="blue"/>
      <origin rpy="0 0 0" xyz="0 0 0"/>
      <geometry>
        <cylinder length="0.10" radius="0.13"/>
      </geometry>
    </visual>
  </link>
</robot>
